Workbook

Sheet TAx4 GPS NED (Kido)
G1: From GPS (Kido, Okuda) | K1: CLF coords (Kido, Okuda) | N1: CLF coords (NED) | Q1: From USGS NED (NED) | U1: Difference
F2: ARRAY | G2: site | H2: lat | I2: lon | J2: h0 | K2: east (m) | L2: north (m) | M2: up (m) | N2: east (m) | O2: north (m) | P2: up (m) | Q2: ned | R2: ortho | S2: SD h | T2: h' | U2: h-h' | V2: Z | W2: |Z|>3 | X2: h_pred | Y2: delta
A3: {=LOOKUP(1,1/FREQUENCY(0,MMULT((TA_AllSites_20220124!$A$2:$B$1397-$H3:$I3)^2,{1;1})),TA_AllSites_20220124!$C$2:$C$1397)} -> #N/A | B3: {=LOOKUP(1,1/FREQUENCY(0,SIN((RADIANS(TA_AllSites_20220124!$A$2:$A$1397-$H3))/2)^2+SIN((RADIANS(TA_AllSites_20220124!$B$2:$B$1397-$I3))/2)^2*COS(RADIANS(TA_AllSites_20220124!$A$2:$A$1397))*COS(RADIANS($H3))),TA_AllSites_20220124!$A$2:$A$1397)} -> 39.29693 | C3: {=LOOKUP(1,1/FREQUENCY(0,SIN((RADIANS(TA_AllSites_20220124!$A$2:$A$1397-$H3))/2)^2+SIN((RADIANS(TA_AllSites_20220124!$B$2:$B$1397-$I3))/2)^2*COS(RADIANS(TA_AllSites_20220124!$A$2:$A$1397))*COS(RADIANS($H3))),TA_AllSites_20220124!$B$2:$B$1397)} -> -112.90875 | F3: TA | G3: 106 | H3: 39.184032 | I3: -113.06582 | J3: 1513.52 | K3: -13575.37 | L3: -12523.793 | M3: 116.724 | N3: -13575.363 | O3: -12523.787 | P3: 113.614 | Q3: 1529.48 | R3: -20.072 | S3: 0.89 | T3: =Q3+R3+S3 -> 1510.298 | U3: =$J3-$T3 -> 3.222 | V3: =($U3-$AC$4)/$AC$7 -> -1.6728858 | W3: =if(abs($V3)>3,"✔","") | X3: =$J3-$AC$4 -> 1508.968 | Y3: =T3-X3 -> 1.33 | AA3: Stats | AB3: Q1 | AC3: =quartile($U$3:$U$838,1) -> 3.999 | AE3: Stats | AF3: Q1 | AG3: =quartile($Y$3:$Y$838,1) -> -0.5195
A4: {=LOOKUP(1,1/FREQUENCY(0,SIN((RADIANS(TA_AllSites_20220124!$A$2:$A$1397-$H4))/2)^2+SIN((RADIANS(TA_AllSites_20220124!$B$2:$B$1397-$I4))/2)^2*COS(RADIANS(TA_AllSites_20220124!$A$2:$A$1397))*COS(RADIANS($H4))),TA_AllSites_20220124!$C$2:$C$1397)} -> CLF | B4: {=LOOKUP(1,1/FREQUENCY(0,SIN((RADIANS(TA_AllSites_20220124!$A$2:$A$1397-$H4))/2)^2+SIN((RADIANS(TA_AllSites_20220124!$B$2:$B$1397-$I4))/2)^2*COS(RADIANS(TA_AllSites_20220124!$A$2:$A$1397))*COS(RADIANS($H4))),TA_AllSites_20220124!$A$2:$A$1397)} -> 39.29693 | C4: {=LOOKUP(1,1/FREQUENCY(0,SIN((RADIANS(TA_AllSites_20220124!$A$2:$A$1397-$H4))/2)^2+SIN((RADIANS(TA_AllSites_20220124!$B$2:$B$1397-$I4))/2)^2*COS(RADIANS(TA_AllSites_20220124!$A$2:$A$1397))*COS(RADIANS($H4))),TA_AllSites_20220124!$B$2:$B$1397)} -> -112.90875 | F4: TA | G4: 107 | H4: 39.195007 | I4: -113.06521 | J4: 1496.78 | K4: -13521.205 | L4: -11305.133 | M4: 102.381 | N4: -13521.195 | O4: -11305.125 | P4: 97.831 | Q4: 1511.28 | R4: -20.055 | S4: 0.89 | T4: =Q4+R4+S4 -> 1492.115 | U4: =$J4-$T4 -> 4.665 | V4: =($U4-$AC$4)/$AC$7 -> 0.1421324 | W4: =if(abs($V4)>3,"✔","") | X4: =$J4-$AC$4 -> 1492.228 | Y4: =T4-X4 -> -0.113 | AB4: Q2 | AC4: =quartile($U$3:$U$838,2) -> 4.552 | AF4: Q2 | AG4: =quartile($Y$3:$Y$838,2) -> 0
A5: {=LOOKUP(1,1/FREQUENCY(0,SIN((RADIANS(TA_AllSites_20220124!$A$2:$A$1397-$H5))/2)^2+SIN((RADIANS(TA_AllSites_20220124!$B$2:$B$1397-$I5))/2)^2*COS(RADIANS(TA_AllSites_20220124!$A$2:$A$1397))*COS(RADIANS($H5))),TA_AllSites_20220124!$C$2:$C$1397)} -> CLF | B5: {=LOOKUP(1,1/FREQUENCY(0,SIN((RADIANS(TA_AllSites_20220124!$A$2:$A$1397-$H5))/2)^2+SIN((RADIANS(TA_AllSites_20220124!$B$2:$B$1397-$I5))/2)^2*COS(RADIANS(TA_AllSites_20220124!$A$2:$A$1397))*COS(RADIANS($H5))),TA_AllSites_20220124!$A$2:$A$1397)} -> 39.29693 | C5: {=LOOKUP(1,1/FREQUENCY(0,SIN((RADIANS(TA_AllSites_20220124!$A$2:$A$1397-$H5))/2)^2+SIN((RADIANS(TA_AllSites_20220124!$B$2:$B$1397-$I5))/2)^2*COS(RADIANS(TA_AllSites_20220124!$A$2:$A$1397))*COS(RADIANS($H5))),TA_AllSites_20220124!$B$2:$B$1397)} -> -112.90875 | F5: TA | G5: 108 | H5: 39.20562 | I5: -113.06496 | J5: 1487.35 | K5: -13497.552 | L5: -10126.633 | M5: 94.986 | N5: -13497.543 | O5: -10126.627 | P5: 90.686 | Q5: 1502.09 | R5: -20.04 | S5: 0.89 | T5: =Q5+R5+S5 -> 1482.94 | U5: =$J5-$T5 -> 4.41 | V5: =($U5-$AC$4)/$AC$7 -> -0.17860886 | W5: =if(abs($V5)>3,"✔","") | X5: =$J5-$AC$4 -> 1482.798 | Y5: =T5-X5 -> 0.142 | AB5: Q3 | AC5: =quartile($U$3:$U$838,3) -> 5.0715 | AF5: Q3 | AG5: =quartile($Y$3:$Y$838,3) -> 0.553
A6: {=LOOKUP(1,1/FREQUENCY(0,SIN((RADIANS(TA_AllSites_20220124!$A$2:$A$1397-$H6))/2)^2+SIN((RADIANS(TA_AllSites_20220124!$B$2:$B$1397-$I6))/2)^2*COS(RADIANS(TA_AllSites_20220124!$A$2:$A$1397))*COS(RADIANS($H6))),TA_AllSites_20220124!$C$2:$C$1397)} -> CLF | B6: {=LOOKUP(1,1/FREQUENCY(0,SIN((RADIANS(TA_AllSites_20220124!$A$2:$A$1397-$H6))/2)^2+SIN((RADIANS(TA_AllSites_20220124!$B$2:$B$1397-$I6))/2)^2*COS(RADIANS(TA_AllSites_20220124!$A$2:$A$1397))*COS(RADIANS($H6))),TA_AllSites_20220124!$A$2:$A$1397)} -> 39.29693 | C6: {=LOOKUP(1,1/FREQUENCY(0,SIN((RADIANS(TA_AllSites_20220124!$A$2:$A$1397-$H6))/2)^2+SIN((RADIANS(TA_AllSites_20220124!$B$2:$B$1397-$I6))/2)^2*COS(RADIANS(TA_AllSites_20220124!$A$2:$A$1397))*COS(RADIANS($H6))),TA_AllSites_20220124!$B$2:$B$1397)} -> -112.90875 | F6: TA | G6: 109 | H6: 39.216567 | I6: -113.06512 | J6: 1489.69 | K6: -13508.592 | L6: -8911.002 | M6: 99.121 | N6: -13508.582 | O6: -8910.996 | P6: 94.721 | Q6: 1504.31 | R6: -20.024 | S6: 0.89 | T6: =Q6+R6+S6 -> 1485.176 | U6: =$J6-$T6 -> 4.514 | V6: =($U6-$AC$4)/$AC$7 -> -0.047796737 | W6: =if(abs($V6)>3,"✔","") | X6: =$J6-$AC$4 -> 1485.138 | Y6: =T6-X6 -> 0.038 | AB6: IQR | AC6: =(AC5-AC3) -> 1.0725 | AF6: IQR | AG6: =(AG5-AG3) -> 1.0725
A7: {=LOOKUP(1,1/FREQUENCY(0,SIN((RADIANS(TA_AllSites_20220124!$A$2:$A$1397-$H7))/2)^2+SIN((RADIANS(TA_AllSites_20220124!$B$2:$B$1397-$I7))/2)^2*COS(RADIANS(TA_AllSites_20220124!$A$2:$A$1397))*COS(RADIANS($H7))),TA_AllSites_20220124!$C$2:$C$1397)} -> CLF | B7: {=LOOKUP(1,1/FREQUENCY(0,SIN((RADIANS(TA_AllSites_20220124!$A$2:$A$1397-$H7))/2)^2+SIN((RADIANS(TA_AllSites_20220124!$B$2:$B$1397-$I7))/2)^2*COS(RADIANS(TA_AllSites_20220124!$A$2:$A$1397))*COS(RADIANS($H7))),TA_AllSites_20220124!$A$2:$A$1397)} -> 39.29693 | C7: {=LOOKUP(1,1/FREQUENCY(0,SIN((RADIANS(TA_AllSites_20220124!$A$2:$A$1397-$H7))/2)^2+SIN((RADIANS(TA_AllSites_20220124!$B$2:$B$1397-$I7))/2)^2*COS(RADIANS(TA_AllSites_20220124!$A$2:$A$1397))*COS(RADIANS($H7))),TA_AllSites_20220124!$B$2:$B$1397)} -> -112.90875 | F7: TA | G7: 110 | H7: 39.227616 | I7: -113.06534 | J7: 1489.63 | K7: -13525.82 | L7: -7684.028 | M7: 100.625 | N7: -13525.811 | O7: -7684.022 | P7: 96.355 | Q7: 1504.37 | R7: -20.01 | S7: 0.89 | T7: =Q7+R7+S7 -> 1485.25 | U7: =$J7-$T7 -> 4.38 | V7: =($U7-$AC$4)/$AC$7 -> -0.21634312 | W7: =if(abs($V7)>3,"✔","") | X7: =$J7-$AC$4 -> 1485.078 | Y7: =T7-X7 -> 0.172 | AB7: iqrSD | AC7: =$AC$6/1.349 -> 0.79503336 | AF7: iqrSD | AG7: =$AC$6/1.349 -> 0.79503336
A8: {=LOOKUP(1,1/FREQUENCY(0,SIN((RADIANS(TA_AllSites_20220124!$A$2:$A$1397-$H8))/2)^2+SIN((RADIANS(TA_AllSites_20220124!$B$2:$B$1397-$I8))/2)^2*COS(RADIANS(TA_AllSites_20220124!$A$2:$A$1397))*COS(RADIANS($H8))),TA_AllSites_20220124!$C$2:$C$1397)} -> CLF | B8: {=LOOKUP(1,1/FREQUENCY(0,SIN((RADIANS(TA_AllSites_20220124!$A$2:$A$1397-$H8))/2)^2+SIN((RADIANS(TA_AllSites_20220124!$B$2:$B$1397-$I8))/2)^2*COS(RADIANS(TA_AllSites_20220124!$A$2:$A$1397))*COS(RADIANS($H8))),TA_AllSites_20220124!$A$2:$A$1397)} -> 39.29693 | C8: {=LOOKUP(1,1/FREQUENCY(0,SIN((RADIANS(TA_AllSites_20220124!$A$2:$A$1397-$H8))/2)^2+SIN((RADIANS(TA_AllSites_20220124!$B$2:$B$1397-$I8))/2)^2*COS(RADIANS(TA_AllSites_20220124!$A$2:$A$1397))*COS(RADIANS($H8))),TA_AllSites_20220124!$B$2:$B$1397)} -> -112.90875 | F8: TA | G8: 111 | H8: 39.238226 | I8: -113.06465 | J8: 1475.45 | K8: -13464.255 | L8: -6505.921 | M8: 87.888 | N8: -13464.245 | O8: -6505.916 | P8: 83.178 | Q8: 1489.74 | R8: -20 | S8: 0.89 | T8: =Q8+R8+S8 -> 1470.63 | U8: =$J8-$T8 -> 4.82 | V8: =($U8-$AC$4)/$AC$7 -> 0.33709277 | W8: =if(abs($V8)>3,"✔","") | X8: =$J8-$AC$4 -> 1470.898 | Y8: =T8-X8 -> -0.268 | AB8: mean | AC8: =average($U$3:$U$838) -> 4.534006 | AF8: mean | AG8: =average($Y$3:$Y$838) -> 0.017994019
A9: {=LOOKUP(1,1/FREQUENCY(0,SIN((RADIANS(TA_AllSites_20220124!$A$2:$A$1397-$H9))/2)^2+SIN((RADIANS(TA_AllSites_20220124!$B$2:$B$1397-$I9))/2)^2*COS(RADIANS(TA_AllSites_20220124!$A$2:$A$1397))*COS(RADIANS($H9))),TA_AllSites_20220124!$C$2:$C$1397)} -> CLF | B9: {=LOOKUP(1,1/FREQUENCY(0,SIN((RADIANS(TA_AllSites_20220124!$A$2:$A$1397-$H9))/2)^2+SIN((RADIANS(TA_AllSites_20220124!$B$2:$B$1397-$I9))/2)^2*COS(RADIANS(TA_AllSites_20220124!$A$2:$A$1397))*COS(RADIANS($H9))),TA_AllSites_20220124!$A$2:$A$1397)} -> 39.29693 | C9: {=LOOKUP(1,1/FREQUENCY(0,SIN((RADIANS(TA_AllSites_20220124!$A$2:$A$1397-$H9))/2)^2+SIN((RADIANS(TA_AllSites_20220124!$B$2:$B$1397-$I9))/2)^2*COS(RADIANS(TA_AllSites_20220124!$A$2:$A$1397))*COS(RADIANS($H9))),TA_AllSites_20220124!$B$2:$B$1397)} -> -112.90875 | F9: TA | G9: 112 | H9: 39.249013 | I9: -113.06512 | J9: 1460.31 | K9: -13502.569 | L9: -5307.989 | M9: 73.78 | N9: -13502.559 | O9: -5307.985 | P9: 69.18 | Q9: 1474.7 | R9: -19.99 | S9: 0.89 | T9: =Q9+R9+S9 -> 1455.6 | U9: =$J9-$T9 -> 4.71 | V9: =($U9-$AC$4)/$AC$7 -> 0.1987338 | W9: =if(abs($V9)>3,"✔","") | X9: =$J9-$AC$4 -> 1455.758 | Y9: =T9-X9 -> -0.158 | AB9: SD | AC9: =stdev($U$3:$U$838) -> 0.93054615 | AF9: SD | AG9: =stdev($Y$3:$Y$838) -> 0.93054615
A10: {=LOOKUP(1,1/FREQUENCY(0,SIN((RADIANS(TA_AllSites_20220124!$A$2:$A$1397-$H10))/2)^2+SIN((RADIANS(TA_AllSites_20220124!$B$2:$B$1397-$I10))/2)^2*COS(RADIANS(TA_AllSites_20220124!$A$2:$A$1397))*COS(RADIANS($H10))),TA_AllSites_20220124!$C$2:$C$1397)} -> CLF | B10: {=LOOKUP(1,1/FREQUENCY(0,SIN((RADIANS(TA_AllSites_20220124!$A$2:$A$1397-$H10))/2)^2+SIN((RADIANS(TA_AllSites_20220124!$B$2:$B$1397-$I10))/2)^2*COS(RADIANS(TA_AllSites_20220124!$A$2:$A$1397))*COS(RADIANS($H10))),TA_AllSites_20220124!$A$2:$A$1397)} -> 39.29693 | C10: {=LOOKUP(1,1/FREQUENCY(0,SIN((RADIANS(TA_AllSites_20220124!$A$2:$A$1397-$H10))/2)^2+SIN((RADIANS(TA_AllSites_20220124!$B$2:$B$1397-$I10))/2)^2*COS(RADIANS(TA_AllSites_20220124!$A$2:$A$1397))*COS(RADIANS($H10))),TA_AllSites_20220124!$B$2:$B$1397)} -> -112.90875 | F10: TA | G10: 113 | H10: 39.26015 | I10: -113.0648 | J10: 1451.76 | K10: -13473.135 | L10: -4071.315 | M10: 66.203 | N10: -13473.124 | O10: -4071.312 | P10: 61.003 | Q10: 1465.54 | R10: -19.98 | S10: 0.89 | T10: =Q10+R10+S10 -> 1446.45 | U10: =$J10-$T10 -> 5.31 | V10: =($U10-$AC$4)/$AC$7 -> 0.95341911 | W10: =if(abs($V10)>3,"✔","") | X10: =$J10-$AC$4 -> 1447.208 | Y10: =T10-X10 -> -0.758
A11: {=LOOKUP(1,1/FREQUENCY(0,SIN((RADIANS(TA_AllSites_20220124!$A$2:$A$1397-$H11))/2)^2+SIN((RADIANS(TA_AllSites_20220124!$B$2:$B$1397-$I11))/2)^2*COS(RADIANS(TA_AllSites_20220124!$A$2:$A$1397))*COS(RADIANS($H11))),TA_AllSites_20220124!$C$2:$C$1397)} -> CLF | B11: {=LOOKUP(1,1/FREQUENCY(0,SIN((RADIANS(TA_AllSites_20220124!$A$2:$A$1397-$H11))/2)^2+SIN((RADIANS(TA_AllSites_20220124!$B$2:$B$1397-$I11))/2)^2*COS(RADIANS(TA_AllSites_20220124!$A$2:$A$1397))*COS(RADIANS($H11))),TA_AllSites_20220124!$A$2:$A$1397)} -> 39.29693 | C11: {=LOOKUP(1,1/FREQUENCY(0,SIN((RADIANS(TA_AllSites_20220124!$A$2:$A$1397-$H11))/2)^2+SIN((RADIANS(TA_AllSites_20220124!$B$2:$B$1397-$I11))/2)^2*COS(RADIANS(TA_AllSites_20220124!$A$2:$A$1397))*COS(RADIANS($H11))),TA_AllSites_20220124!$B$2:$B$1397)} -> -112.90875 | F11: TA | G11: 114 | H11: 39.270623 | I11: -113.06517 | J11: 1457.07 | K11: -13502.56 | L11: -2908.282 | M11: 72.089 | N11: -13502.548 | O11: -2908.279 | P11: 66.389 | Q11: 1470.34 | R11: -19.968 | S11: 0.89 | T11: =Q11+R11+S11 -> 1451.262 | U11: =$J11-$T11 -> 5.808 | V11: =($U11-$AC$4)/$AC$7 -> 1.5798079 | W11: =if(abs($V11)>3,"✔","") | X11: =$J11-$AC$4 -> 1452.518 | Y11: =T11-X11 -> -1.256
A12: {=LOOKUP(1,1/FREQUENCY(0,SIN((RADIANS(TA_AllSites_20220124!$A$2:$A$1397-$H12))/2)^2+SIN((RADIANS(TA_AllSites_20220124!$B$2:$B$1397-$I12))/2)^2*COS(RADIANS(TA_AllSites_20220124!$A$2:$A$1397))*COS(RADIANS($H12))),TA_AllSites_20220124!$C$2:$C$1397)} -> CLF | B12: {=LOOKUP(1,1/FREQUENCY(0,SIN((RADIANS(TA_AllSites_20220124!$A$2:$A$1397-$H12))/2)^2+SIN((RADIANS(TA_AllSites_20220124!$B$2:$B$1397-$I12))/2)^2*COS(RADIANS(TA_AllSites_20220124!$A$2:$A$1397))*COS(RADIANS($H12))),TA_AllSites_20220124!$A$2:$A$1397)} -> 39.29693 | C12: {=LOOKUP(1,1/FREQUENCY(0,SIN((RADIANS(TA_AllSites_20220124!$A$2:$A$1397-$H12))/2)^2+SIN((RADIANS(TA_AllSites_20220124!$B$2:$B$1397-$I12))/2)^2*COS(RADIANS(TA_AllSites_20220124!$A$2:$A$1397))*COS(RADIANS($H12))),TA_AllSites_20220124!$B$2:$B$1397)} -> -112.90875 | F12: TA | G12: 115 | H12: 39.281859 | I12: -113.06514 | J12: 1460.64 | K12: -13497.995 | L12: -1660.574 | M12: 76.117 | N12: -13497.986 | O12: -1660.573 | P12: 72.207 | Q12: 1475.68 | R12: -19.953 | S12: 0.89 | T12: =Q12+R12+S12 -> 1456.617 | U12: =$J12-$T12 -> 4.023 | V12: =($U12-$AC$4)/$AC$7 -> -0.66538089 | W12: =if(abs($V12)>3,"✔","") | X12: =$J12-$AC$4 -> 1456.088 | Y12: =T12-X12 -> 0.529
A13: {=LOOKUP(1,1/FREQUENCY(0,SIN((RADIANS(TA_AllSites_20220124!$A$2:$A$1397-$H13))/2)^2+SIN((RADIANS(TA_AllSites_20220124!$B$2:$B$1397-$I13))/2)^2*COS(RADIANS(TA_AllSites_20220124!$A$2:$A$1397))*COS(RADIANS($H13))),TA_AllSites_20220124!$C$2:$C$1397)} -> CLF | B13: {=LOOKUP(1,1/FREQUENCY(0,SIN((RADIANS(TA_AllSites_20220124!$A$2:$A$1397-$H13))/2)^2+SIN((RADIANS(TA_AllSites_20220124!$B$2:$B$1397-$I13))/2)^2*COS(RADIANS(TA_AllSites_20220124!$A$2:$A$1397))*COS(RADIANS($H13))),TA_AllSites_20220124!$A$2:$A$1397)} -> 39.29693 | C13: {=LOOKUP(1,1/FREQUENCY(0,SIN((RADIANS(TA_AllSites_20220124!$A$2:$A$1397-$H13))/2)^2+SIN((RADIANS(TA_AllSites_20220124!$B$2:$B$1397-$I13))/2)^2*COS(RADIANS(TA_AllSites_20220124!$A$2:$A$1397))*COS(RADIANS($H13))),TA_AllSites_20220124!$B$2:$B$1397)} -> -112.90875 | F13: TA | G13: 116 | H13: 39.292247 | I13: -113.06512 | J13: 1474.67 | K13: -13494.477 | L13: -507.029 | M13: 90.351 | N13: -13494.465 | O13: -507.028 | P13: 84.541 | Q13: 1487.8 | R13: -19.936 | S13: 0.89 | T13: =Q13+R13+S13 -> 1468.754 | U13: =$J13-$T13 -> 5.916 | V13: =($U13-$AC$4)/$AC$7 -> 1.7156513 | W13: =if(abs($V13)>3,"✔","") | X13: =$J13-$AC$4 -> 1470.118 | Y13: =T13-X13 -> -1.364
A14: {=LOOKUP(1,1/FREQUENCY(0,SIN((RADIANS(TA_AllSites_20220124!$A$2:$A$1397-$H14))/2)^2+SIN((RADIANS(TA_AllSites_20220124!$B$2:$B$1397-$I14))/2)^2*COS(RADIANS(TA_AllSites_20220124!$A$2:$A$1397))*COS(RADIANS($H14))),TA_AllSites_20220124!$C$2:$C$1397)} -> CLF | B14: {=LOOKUP(1,1/FREQUENCY(0,SIN((RADIANS(TA_AllSites_20220124!$A$2:$A$1397-$H14))/2)^2+SIN((RADIANS(TA_AllSites_20220124!$B$2:$B$1397-$I14))/2)^2*COS(RADIANS(TA_AllSites_20220124!$A$2:$A$1397))*COS(RADIANS($H14))),TA_AllSites_20220124!$A$2:$A$1397)} -> 39.29693 | C14: {=LOOKUP(1,1/FREQUENCY(0,SIN((RADIANS(TA_AllSites_20220124!$A$2:$A$1397-$H14))/2)^2+SIN((RADIANS(TA_AllSites_20220124!$B$2:$B$1397-$I14))/2)^2*COS(RADIANS(TA_AllSites_20220124!$A$2:$A$1397))*COS(RADIANS($H14))),TA_AllSites_20220124!$B$2:$B$1397)} -> -112.90875 | F14: TA | G14: 205 | H14: 39.173319 | I14: -113.05099 | J14: 1442.22 | K14: -12295.81 | L14: -13715.383 | M14: 45.558 | N14: -12295.799 | O14: -13715.371 | P14: 39.888 | Q14: 1455.66 | R14: -20.106 | S14: 0.89 | T14: =Q14+R14+S14 -> 1436.444 | U14: =$J14-$T14 -> 5.776 | V14: =($U14-$AC$4)/$AC$7 -> 1.539558 | W14: =if(abs($V14)>3,"✔","") | X14: =$J14-$AC$4 -> 1437.668 | Y14: =T14-X14 -> -1.224
A15: {=LOOKUP(1,1/FREQUENCY(0,SIN((RADIANS(TA_AllSites_20220124!$A$2:$A$1397-$H15))/2)^2+SIN((RADIANS(TA_AllSites_20220124!$B$2:$B$1397-$I15))/2)^2*COS(RADIANS(TA_AllSites_20220124!$A$2:$A$1397))*COS(RADIANS($H15))),TA_AllSites_20220124!$C$2:$C$1397)} -> CLF | B15: {=LOOKUP(1,1/FREQUENCY(0,SIN((RADIANS(TA_AllSites_20220124!$A$2:$A$1397-$H15))/2)^2+SIN((RADIANS(TA_AllSites_20220124!$B$2:$B$1397-$I15))/2)^2*COS(RADIANS(TA_AllSites_20220124!$A$2:$A$1397))*COS(RADIANS($H15))),TA_AllSites_20220124!$A$2:$A$1397)} -> 39.29693 | C15: {=LOOKUP(1,1/FREQUENCY(0,SIN((RADIANS(TA_AllSites_20220124!$A$2:$A$1397-$H15))/2)^2+SIN((RADIANS(TA_AllSites_20220124!$B$2:$B$1397-$I15))/2)^2*COS(RADIANS(TA_AllSites_20220124!$A$2:$A$1397))*COS(RADIANS($H15))),TA_AllSites_20220124!$B$2:$B$1397)} -> -112.90875 | F15: TA | G15: 206 | H15: 39.184775 | I15: -113.05034 | J15: 1462.95 | K15: -12238.027 | L15: -12443.395 | M15: 69.013 | N15: -12238.019 | O15: -12443.387 | P15: 64.883 | Q15: 1477.9 | R15: -20.085 | S15: 0.89 | T15: =Q15+R15+S15 -> 1458.705 | U15: =$J15-$T15 -> 4.245 | V15: =($U15-$AC$4)/$AC$7 -> -0.38614732 | W15: =if(abs($V15)>3,"✔","") | X15: =$J15-$AC$4 -> 1458.398 | Y15: =T15-X15 -> 0.307
A16: {=LOOKUP(1,1/FREQUENCY(0,SIN((RADIANS(TA_AllSites_20220124!$A$2:$A$1397-$H16))/2)^2+SIN((RADIANS(TA_AllSites_20220124!$B$2:$B$1397-$I16))/2)^2*COS(RADIANS(TA_AllSites_20220124!$A$2:$A$1397))*COS(RADIANS($H16))),TA_AllSites_20220124!$C$2:$C$1397)} -> CLF | B16: {=LOOKUP(1,1/FREQUENCY(0,SIN((RADIANS(TA_AllSites_20220124!$A$2:$A$1397-$H16))/2)^2+SIN((RADIANS(TA_AllSites_20220124!$B$2:$B$1397-$I16))/2)^2*COS(RADIANS(TA_AllSites_20220124!$A$2:$A$1397))*COS(RADIANS($H16))),TA_AllSites_20220124!$A$2:$A$1397)} -> 39.29693 | C16: {=LOOKUP(1,1/FREQUENCY(0,SIN((RADIANS(TA_AllSites_20220124!$A$2:$A$1397-$H16))/2)^2+SIN((RADIANS(TA_AllSites_20220124!$B$2:$B$1397-$I16))/2)^2*COS(RADIANS(TA_AllSites_20220124!$A$2:$A$1397))*COS(RADIANS($H16))),TA_AllSites_20220124!$B$2:$B$1397)} -> -112.90875 | F16: TA | G16: 207 | H16: 39.194913 | I16: -113.05119 | J16: 1460.69 | K16: -12309.452 | L16: -11317.509 | M16: 68.719 | N16: -12309.443 | O16: -11317.501 | P16: 64.149 | Q16: 1475.19 | R16: -20.069 | S16: 0.89 | T16: =Q16+R16+S16 -> 1456.011 | U16: =$J16-$T16 -> 4.679 | V16: =($U16-$AC$4)/$AC$7 -> 0.15974172 | W16: =if(abs($V16)>3,"✔","") | X16: =$J16-$AC$4 -> 1456.138 | Y16: =T16-X16 -> -0.127
A17: {=LOOKUP(1,1/FREQUENCY(0,SIN((RADIANS(TA_AllSites_20220124!$A$2:$A$1397-$H17))/2)^2+SIN((RADIANS(TA_AllSites_20220124!$B$2:$B$1397-$I17))/2)^2*COS(RADIANS(TA_AllSites_20220124!$A$2:$A$1397))*COS(RADIANS($H17))),TA_AllSites_20220124!$C$2:$C$1397)} -> CLF | B17: {=LOOKUP(1,1/FREQUENCY(0,SIN((RADIANS(TA_AllSites_20220124!$A$2:$A$1397-$H17))/2)^2+SIN((RADIANS(TA_AllSites_20220124!$B$2:$B$1397-$I17))/2)^2*COS(RADIANS(TA_AllSites_20220124!$A$2:$A$1397))*COS(RADIANS($H17))),TA_AllSites_20220124!$A$2:$A$1397)} -> 39.29693 | C17: {=LOOKUP(1,1/FREQUENCY(0,SIN((RADIANS(TA_AllSites_20220124!$A$2:$A$1397-$H17))/2)^2+SIN((RADIANS(TA_AllSites_20220124!$B$2:$B$1397-$I17))/2)^2*COS(RADIANS(TA_AllSites_20220124!$A$2:$A$1397))*COS(RADIANS($H17))),TA_AllSites_20220124!$B$2:$B$1397)} -> -112.90875 | F17: TA | G17: 208 | H17: 39.205739 | I17: -113.05121 | J17: 1461.47 | K17: -12309.465 | L17: -10115.339 | M17: 71.523 | N17: -12309.456 | O17: -10115.332 | P17: 67.083 | Q17: 1476.08 | R17: -20.053 | S17: 0.89 | T17: =Q17+R17+S17 -> 1456.917 | U17: =$J17-$T17 -> 4.553 | V17: =($U17-$AC$4)/$AC$7 -> 0.0012578089 | W17: =if(abs($V17)>3,"✔","") | X17: =$J17-$AC$4 -> 1456.918 | Y17: =T17-X17 -> -0.001
A18: {=LOOKUP(1,1/FREQUENCY(0,SIN((RADIANS(TA_AllSites_20220124!$A$2:$A$1397-$H18))/2)^2+SIN((RADIANS(TA_AllSites_20220124!$B$2:$B$1397-$I18))/2)^2*COS(RADIANS(TA_AllSites_20220124!$A$2:$A$1397))*COS(RADIANS($H18))),TA_AllSites_20220124!$C$2:$C$1397)} -> CLF | B18: {=LOOKUP(1,1/FREQUENCY(0,SIN((RADIANS(TA_AllSites_20220124!$A$2:$A$1397-$H18))/2)^2+SIN((RADIANS(TA_AllSites_20220124!$B$2:$B$1397-$I18))/2)^2*COS(RADIANS(TA_AllSites_20220124!$A$2:$A$1397))*COS(RADIANS($H18))),TA_AllSites_20220124!$A$2:$A$1397)} -> 39.29693 | C18: {=LOOKUP(1,1/FREQUENCY(0,SIN((RADIANS(TA_AllSites_20220124!$A$2:$A$1397-$H18))/2)^2+SIN((RADIANS(TA_AllSites_20220124!$B$2:$B$1397-$I18))/2)^2*COS(RADIANS(TA_AllSites_20220124!$A$2:$A$1397))*COS(RADIANS($H18))),TA_AllSites_20220124!$B$2:$B$1397)} -> -112.90875 | F18: TA | G18: 209 | H18: 39.216844 | I18: -113.0512 | J18: 1452.88 | K18: -12306.559 | L18: -8882.177 | M18: 64.78 | N18: -12306.55 | O18: -8882.17 | P18: 60.22 | Q18: 1467.36 | R18: -20.038 | S18: 0.89 | T18: =Q18+R18+S18 -> 1448.212 | U18: =$J18-$T18 -> 4.668 | V18: =($U18-$AC$4)/$AC$7 -> 0.14590583 | W18: =if(abs($V18)>3,"✔","") | X18: =$J18-$AC$4 -> 1448.328 | Y18: =T18-X18 -> -0.116
A19: {=LOOKUP(1,1/FREQUENCY(0,SIN((RADIANS(TA_AllSites_20220124!$A$2:$A$1397-$H19))/2)^2+SIN((RADIANS(TA_AllSites_20220124!$B$2:$B$1397-$I19))/2)^2*COS(RADIANS(TA_AllSites_20220124!$A$2:$A$1397))*COS(RADIANS($H19))),TA_AllSites_20220124!$C$2:$C$1397)} -> CLF | B19: {=LOOKUP(1,1/FREQUENCY(0,SIN((RADIANS(TA_AllSites_20220124!$A$2:$A$1397-$H19))/2)^2+SIN((RADIANS(TA_AllSites_20220124!$B$2:$B$1397-$I19))/2)^2*COS(RADIANS(TA_AllSites_20220124!$A$2:$A$1397))*COS(RADIANS($H19))),TA_AllSites_20220124!$A$2:$A$1397)} -> 39.29693 | C19: {=LOOKUP(1,1/FREQUENCY(0,SIN((RADIANS(TA_AllSites_20220124!$A$2:$A$1397-$H19))/2)^2+SIN((RADIANS(TA_AllSites_20220124!$B$2:$B$1397-$I19))/2)^2*COS(RADIANS(TA_AllSites_20220124!$A$2:$A$1397))*COS(RADIANS($H19))),TA_AllSites_20220124!$B$2:$B$1397)} -> -112.90875 | F19: TA | G19: 210 | H19: 39.227348 | I19: -113.05123 | J19: 1444.43 | K19: -12307.041 | L19: -7715.748 | M19: 57.85 | N19: -12307.032 | O19: -7715.742 | P19: 53.421 | Q19: 1459.02 | R19: -20.025 | S19: 0.89 | T19: =Q19+R19+S19 -> 1439.885 | U19: =$J19-$T19 -> 4.545 | V19: =($U19-$AC$4)/$AC$7 -> -0.008804662 | W19: =if(abs($V19)>3,"✔","") | X19: =$J19-$AC$4 -> 1439.878 | Y19: =T19-X19 -> 0.007
A20: {=LOOKUP(1,1/FREQUENCY(0,SIN((RADIANS(TA_AllSites_20220124!$A$2:$A$1397-$H20))/2)^2+SIN((RADIANS(TA_AllSites_20220124!$B$2:$B$1397-$I20))/2)^2*COS(RADIANS(TA_AllSites_20220124!$A$2:$A$1397))*COS(RADIANS($H20))),TA_AllSites_20220124!$C$2:$C$1397)} -> CLF | B20: {=LOOKUP(1,1/FREQUENCY(0,SIN((RADIANS(TA_AllSites_20220124!$A$2:$A$1397-$H20))/2)^2+SIN((RADIANS(TA_AllSites_20220124!$B$2:$B$1397-$I20))/2)^2*COS(RADIANS(TA_AllSites_20220124!$A$2:$A$1397))*COS(RADIANS($H20))),TA_AllSites_20220124!$A$2:$A$1397)} -> 39.29693 | C20: {=LOOKUP(1,1/FREQUENCY(0,SIN((RADIANS(TA_AllSites_20220124!$A$2:$A$1397-$H20))/2)^2+SIN((RADIANS(TA_AllSites_20220124!$B$2:$B$1397-$I20))/2)^2*COS(RADIANS(TA_AllSites_20220124!$A$2:$A$1397))*COS(RADIANS($H20))),TA_AllSites_20220124!$B$2:$B$1397)} -> -112.90875 | F20: TA | G20: 211 | H20: 39.238191 | I20: -113.05121 | J20: 1442.99 | K20: -12303.849 | L20: -6511.688 | M20: 57.763 | N20: -12303.839 | O20: -6511.683 | P20: 52.793 | Q20: 1457.03 | R20: -20.013 | S20: 0.89 | T20: =Q20+R20+S20 -> 1437.907 | U20: =$J20-$T20 -> 5.083 | V20: =($U20-$AC$4)/$AC$7 -> 0.6678965 | W20: =if(abs($V20)>3,"✔","") | X20: =$J20-$AC$4 -> 1438.438 | Y20: =T20-X20 -> -0.531
A21: {=LOOKUP(1,1/FREQUENCY(0,SIN((RADIANS(TA_AllSites_20220124!$A$2:$A$1397-$H21))/2)^2+SIN((RADIANS(TA_AllSites_20220124!$B$2:$B$1397-$I21))/2)^2*COS(RADIANS(TA_AllSites_20220124!$A$2:$A$1397))*COS(RADIANS($H21))),TA_AllSites_20220124!$C$2:$C$1397)} -> CLF | B21: {=LOOKUP(1,1/FREQUENCY(0,SIN((RADIANS(TA_AllSites_20220124!$A$2:$A$1397-$H21))/2)^2+SIN((RADIANS(TA_AllSites_20220124!$B$2:$B$1397-$I21))/2)^2*COS(RADIANS(TA_AllSites_20220124!$A$2:$A$1397))*COS(RADIANS($H21))),TA_AllSites_20220124!$A$2:$A$1397)} -> 39.29693 | C21: {=LOOKUP(1,1/FREQUENCY(0,SIN((RADIANS(TA_AllSites_20220124!$A$2:$A$1397-$H21))/2)^2+SIN((RADIANS(TA_AllSites_20220124!$B$2:$B$1397-$I21))/2)^2*COS(RADIANS(TA_AllSites_20220124!$A$2:$A$1397))*COS(RADIANS($H21))),TA_AllSites_20220124!$B$2:$B$1397)} -> -112.90875 | F21: TA | G21: 212 | H21: 39.248977 | I21: -113.05124 | J21: 1443.88 | K21: -12304.384 | L21: -5313.952 | M21: 59.765 | N21: -12304.375 | O21: -5313.948 | P21: 55.235 | Q21: 1458.35 | R21: -20.001 | S21: 0.89 | T21: =Q21+R21+S21 -> 1439.239 | U21: =$J21-$T21 -> 4.641 | V21: =($U21-$AC$4)/$AC$7 -> 0.11194499 | W21: =if(abs($V21)>3,"✔","") | X21: =$J21-$AC$4 -> 1439.328 | Y21: =T21-X21 -> -0.089
... A48: {=LOOKUP(1,1/FREQUENCY(0,SIN((RADIANS(TA_AllSites_20220124!$A$2:$A$1397-$H48))/2)^2+SIN((RADIANS(TA_AllSites_20220124!$B$2:$B$1397-$I48))/2)^2*COS(RADIANS(TA_AllSites_20220124!$A$2:$A$1397))*COS(RADIANS($H48))),TA_AllSites_20220124!$C$2:$C$1397)} -> CLF | B48: {=LOOKUP(1,1/FREQUENCY(0,SIN((RADIANS(TA_AllSites_20220124!$A$2:$A$1397-$H48))/2)^2+SIN((RADIANS(TA_AllSites_20220124!$B$2:$B$1397-$I48))/2)^2*COS(RADIANS(TA_AllSites_20220124!$A$2:$A$1397))*COS(RADIANS($H48))),TA_AllSites_20220124!$A$2:$A$1397)} -> 39.29693 | C48: {=LOOKUP(1,1/FREQUENCY(0,SIN((RADIANS(TA_AllSites_20220124!$A$2:$A$1397-$H48))/2)^2+SIN((RADIANS(TA_AllSites_20220124!$B$2:$B$1397-$I48))/2)^2*COS(RADIANS(TA_AllSites_20220124!$A$2:$A$1397))*COS(RADIANS($H48))),TA_AllSites_20220124!$B$2:$B$1397)} -> -112.90875 | F48: TA | G48: 409 | H48: 39.216593 | I48: -113.02344 | J48: 1429 | K48: -9908.972 | L48: -8913.423 | M48: 45.025 | N48: -9908.966 | O48: -8913.418 | P48: 41.295 | Q48: 1444.33 | R48: -20.059 | S48: 0.89 | T48: =Q48+R48+S48 -> 1425.161 | U48: =$J48-$T48 -> 3.839 | V48: =($U48-$AC$4)/$AC$7 -> -0.89681772 | W48: =if(abs($V48)>3,"✔","") | X48: =$J48-$AC$4 -> 1424.448 | Y48: =T48-X48 -> 0.713
F49: TA | G49: 410 | H49: 39.22738 | I49: -113.02344 | J49: 1423.22 | K49: -9906.583 | L49: -7715.581 | M49: 40.814 | N49: -9906.578 | O49: -7715.577 | P49: 37.564 | Q49: 1439.01 | R49: -20.045 | S49: 0.89 | T49: =Q49+R49+S49 -> 1419.855 | U49: =$J49-$T49 -> 3.365 | V49: =($U49-$AC$4)/$AC$7 -> -1.4930191 | W49: =if(abs($V49)>3,"✔","") | X49: =$J49-$AC$4 -> 1418.668 | Y49: =T49-X49 -> 1.187
F50: TA | G50: 411 | H50: 39.238229 | I50: -113.02332 | J50: 1427.55 | K50: -9895.047 | L50: -6510.875 | M50: 46.509 | N50: -9895.041 | O50: -6510.871 | P50: 42.519 | Q50: 1442.59 | R50: -20.031 | S50: 0.89 | T50: =Q50+R50+S50 -> 1423.449 | U50: =$J50-$T50 -> 4.101 | V50: =($U50-$AC$4)/$AC$7 -> -0.56727179 | W50: =if(abs($V50)>3,"✔","") | X50: =$J50-$AC$4 -> 1422.998 | Y50: =T50-X50 -> 0.451
F51: TA | G51: 412 | H51: 39.249064 | I51: -113.02354 | J51: 1431.78 | K51: -9912.181 | L51: -5307.683 | M51: 51.83 | N51: -9912.174 | O51: -5307.679 | P51: 46.97 | Q51: 1445.94 | R51: -20.018 | S51: 0.89 | T51: =Q51+R51+S51 -> 1426.812 | U51: =$J51-$T51 -> 4.968 | V51: =($U51-$AC$4)/$AC$7 -> 0.52324848 | W51: =if(abs($V51)>3,"✔","") | X51: =$J51-$AC$4 -> 1427.228 | Y51: =T51-X51 -> -0.416
F52: TA | G52: 413 | H52: 39.25978 | I52: -113.02336 | J52: 1435.52 | K52: -9896.003 | L52: -4117.744 | M52: 56.476 | N52: -9895.994 | O52: -4117.74 | P52: 51.186 | Q52: 1449.23 | R52: -20.005 | S52: 0.89 | T52: =Q52+R52+S52 -> 1430.115 | U52: =$J52-$T52 -> 5.405 | V52: =($U52-$AC$4)/$AC$7 -> 1.072911 | W52: =if(abs($V52)>3,"✔","") | X52: =$J52-$AC$4 -> 1430.968 | Y52: =T52-X52 -> -0.853
F53: TA | G53: 414 | H53: 39.270595 | I53: -113.02338 | J53: 1426.57 | K53: -9895.676 | L53: -2916.781 | M53: 48.191 | N53: -9895.669 | O53: -2916.779 | P53: 43.481 | Q53: 1440.85 | R53: -19.99 | S53: 0.89 | T53: =Q53+R53+S53 -> 1421.75 | U53: =$J53-$T53 -> 4.82 | V53: =($U53-$AC$4)/$AC$7 -> 0.33709277 | W53: =if(abs($V53)>3,"✔","") | X53: =$J53-$AC$4 -> 1422.018 | Y53: =T53-X53 -> -0.268
F54: TA | G54: 415 | H54: 39.281466 | I54: -113.02341 | J54: 1426.55 | K54: -9896.909 | L54: -1709.601 | M54: 48.608 | N54: -9896.902 | O54: -1709.6 | P54: 43.948 | Q54: 1440.86 | R54: -19.975 | S54: 0.89 | T54: =Q54+R54+S54 -> 1421.775 | U54: =$J54-$T54 -> 4.775 | V54: =($U54-$AC$4)/$AC$7 -> 0.28049138 | W54: =if(abs($V54)>3,"✔","") | X54: =$J54-$AC$4 -> 1421.998 | Y54: =T54-X54 -> -0.223
F55: TA | G55: 416 | H55: 39.291998 | I55: -113.02341 | J55: 1433.06 | K55: -9895.005 | L55: -540.068 | M55: 55.328 | N55: -9894.996 | O55: -540.068 | P55: 49.188 | Q55: 1445.88 | R55: -19.958 | S55: 0.89 | T55: =Q55+R55+S55 -> 1426.812 | U55: =$J55-$T55 -> 6.248 | V55: =($U55-$AC$4)/$AC$7 -> 2.1332438 | W55: =if(abs($V55)>3,"✔","") | X55: =$J55-$AC$4 -> 1428.508 | Y55: =T55-X55 -> -1.696
F56: TA | G56: 417 | H56: 39.303059 | I56: -113.0234 | J56: 1440.34 | K56: -9893.114 | L56: 688.213 | M56: 62.596 | N56: -9893.109 | O56: 688.212 | P56: 59.326 | Q56: 1456.01 | R56: -19.939 | S56: 0.89 | T56: =Q56+R56+S56 -> 1436.961 | U56: =$J56-$T56 -> 3.379 | V56: =($U56-$AC$4)/$AC$7 -> -1.4754098 | W56: =if(abs($V56)>3,"✔","") | X56: =$J56-$AC$4 -> 1435.788 | Y56: =T56-X56 -> 1.173
F57: TA | G57: 418 | H57: 39.313853 | I57: -113.02341 | J57: 1448.09 | K57: -9892.124 | L57: 1886.851 | M57: 70.105 | N57: -9892.116 | O57: 1886.849 | P57: 64.525 | Q57: 1461.43 | R57: -19.919 | S57: 0.89 | T57: =Q57+R57+S57 -> 1442.401 | U57: =$J57-$T57 -> 5.689 | V57: =($U57-$AC$4)/$AC$7 -> 1.4301287 | W57: =if(abs($V57)>3,"✔","") | X57: =$J57-$AC$4 -> 1443.538 | Y57: =T57-X57 -> -1.137
F58: TA | G58: 419 | H58: 39.324654 | I58: -113.02307 | J58: 1457 | K58: -9861.81 | L58: 3086.235 | M58: 78.593 | N58: -9861.801 | O58: 3086.232 | P58: 72.573 | Q58: 1469.88 | R58: -19.897 | S58: 0.89 | T58: =Q58+R58+S58 -> 1450.873 | U58: =$J58-$T58 -> 6.127 | V58: =($U58-$AC$4)/$AC$7 -> 1.981049 | W58: =if(abs($V58)>3,"✔","") | X58: =$J58-$AC$4 -> 1452.448 | Y58: =T58-X58 -> -1.575
F59: TA | G59: 502 | H59: 39.140856 | I59: -113.00935 | J59: 1384.15 | K59: -8700.617 | L59: -17324.854 | M59: -15.409 | N59: -8700.612 | O59: -17324.844 | P59: -18.969 | Q59: 1399.76 | R59: -20.171 | S59: 0.89 | T59: =Q59+R59+S59 -> 1380.479 | U59: =$J59-$T59 -> 3.671 | V59: =($U59-$AC$4)/$AC$7 -> -1.1081296 | W59: =if(abs($V59)>3,"✔","") | X59: =$J59-$AC$4 -> 1379.598 | Y59: =T59-X59 -> 0.881
F60: TA | G60: 503 | H60: 39.151722 | I60: -113.00956 | J60: 1392.92 | K60: -8717.62 | L60: -16118.273 | M60: -3.491 | N60: -8717.616 | O60: -16118.265 | P60: -6.951 | Q60: 1408.62 | R60: -20.157 | S60: 0.89 | T60: =Q60+R60+S60 -> 1389.353 | U60: =$J60-$T60 -> 3.567 | V60: =($U60-$AC$4)/$AC$7 -> -1.2389417 | W60: =if(abs($V60)>3,"✔","") | X60: =$J60-$AC$4 -> 1388.368 | Y60: =T60-X60 -> 0.985
... F206: TA | G206: 1108 | H206: 39.205714 | I206: -112.92612 | J206: 1375.86 | K206: -1501.821 | L206: -10127.528 | M206: -2.423 | N206: -1501.82 | O206: -10127.521 | P206: -6.743 | Q206: 1390.57 | R206: -20.035 | S206: 0.89 | T206: =Q206+R206+S206 -> 1371.425 | U206: =$J206-$T206 -> 4.435 | V206: =($U206-$AC$4)/$AC$7 -> -0.14716364 | W206: =if(abs($V206)>3,"✔","") | X206: =$J206-$AC$4 -> 1371.308 | Y206: =T206-X206 -> 0.117
F207: TA | G207: 1109 | H207: 39.216545 | I207: -112.92609 | J207: 1375.78 | K207: -1499.258 | L207: -8924.817 | M207: -0.702 | N207: -1499.257 | O207: -8924.812 | P207: -4.932 | Q207: 1390.57 | R207: -20.022 | S207: 0.89 | T207: =Q207+R207+S207 -> 1371.438 | U207: =$J207-$T207 -> 4.342 | V207: =($U207-$AC$4)/$AC$7 -> -0.26413986 | W207: =if(abs($V207)>3,"✔","") | X207: =$J207-$AC$4 -> 1371.228 | Y207: =T207-X207 -> 0.21 | Z207: JAM OPUS Survey values SD1110
F208: TA | G208: 1110 | H208: 39.227316 | I208: -112.92609 | J208: 1377.31 | K208: -1498.771 | L208: -7728.768 | M208: 2.394 | N208: -1498.769 | O208: -7728.762 | P208: -2.556 | Q208: 1391.37 | R208: -20.01 | S208: 0.89 | T208: =Q208+R208+S208 -> 1372.25 | U208: =$J208-$T208 -> 5.06 | V208: =($U208-$AC$4)/$AC$7 -> 0.6389669 | W208: =if(abs($V208)>3,"✔","") | X208: =$J208-$AC$4 -> 1372.758 | Y208: =T208-X208 -> -0.508 | Z208: 1371.137 | AA208: 1391.142 | AB208: 1370.415
F209: TA | G209: 1111 | H209: 39.238143 | I209: -112.9261 | J209: 1379.82 | K209: -1499.577 | L209: -6526.499 | M209: 6.251 | N209: -1499.576 | O209: -6526.494 | P209: 1.411 | Q209: 1393.98 | R209: -19.997 | S209: 0.89 | T209: =Q209+R209+S209 -> 1374.873 | U209: =$J209-$T209 -> 4.947 | V209: =($U209-$AC$4)/$AC$7 -> 0.4968345 | W209: =if(abs($V209)>3,"✔","") | X209: =$J209-$AC$4 -> 1375.268 | Y209: =T209-X209 -> -0.395 | Z209: =Z208-Q208-R208 -> -0.223 | AA209: =AA208-Q208 -> -0.228 | AB209: =Z208-AB208 -> 0.722
F210: TA | G210: 1112 | H210: 39.248987 | I210: -112.92609 | J210: 1379.5 | K210: -1498.31 | L210: -5322.336 | M210: 7.052 | N210: -1498.309 | O210: -5322.332 | P210: 3.122 | Q210: 1394.55 | R210: -19.985 | S210: 0.89 | T210: =Q210+R210+S210 -> 1375.455 | U210: =$J210-$T210 -> 4.045 | V210: =($U210-$AC$4)/$AC$7 -> -0.63770909 | W210: =if(abs($V210)>3,"✔","") | X210: =$J210-$AC$4 -> 1374.948 | Y210: =T210-X210 -> 0.507
F211: TA | G211: 1113 | H211: 39.25979 | I211: -112.92603 | J211: 1380.35 | K211: -1493.678 | L211: -4122.724 | M211: 8.794 | N211: -1493.677 | O211: -4122.721 | P211: 3.854 | Q211: 1394.38 | R211: -19.972 | S211: 0.89 | T211: =Q211+R211+S211 -> 1375.298 | U211: =$J211-$T211 -> 5.052 | V211: =($U211-$AC$4)/$AC$7 -> 0.62890443 | W211: =if(abs($V211)>3,"✔","") | X211: =$J211-$AC$4 -> 1375.798 | Y211: =T211-X211 -> -0.5
...

Sheet enu_okuda
A1: 106 | B1: -13575.37 | C1: -12523.793 | D1: 116.724
A2: 107 | B2: -13521.205 | C2: -11305.133 | D2: 102.381
A3: 108 | B3: -13497.552 | C3: -10126.633 | D3: 94.986
A4: 109 | B4: -13508.592 | C4: -8911.002 | D4: 99.121
A5: 110 | B5: -13525.82 | C5: -7684.028 | D5: 100.625
A6: 111 | B6: -13464.255 | C6: -6505.921 | D6: 87.888
A7: 112 | B7: -13502.569 | C7: -5307.989 | D7: 73.78
A8: 113 | B8: -13473.135 | C8: -4071.315 | D8: 66.203
A9: 114 | B9: -13502.56 | C9: -2908.282 | D9: 72.089
A10: 115 | B10: -13497.995 | C10: -1660.574 | D10: 76.117
A11: 116 | B11: -13494.477 | C11: -507.029 | D11: 90.351
A12: 205 | B12: -12295.81 | C12: -13715.383 | D12: 45.558
... A836: 7809 | B836: 9488.887 | C836: 48749.76 | D836: -46.701

Sheet enu_ned
A1: 106 | B1: -13575.363 | C1: -12523.787 | D1: 113.614
A2: 107 | B2: -13521.195 | C2: -11305.125 | D2: 97.831
A3: 108 | B3: -13497.543 | C3: -10126.627 | D3: 90.686
A4: 109 | B4: -13508.582 | C4: -8910.996 | D4: 94.721
A5: 110 | B5: -13525.811 | C5: -7684.022 | D5: 96.355
A6: 111 | B6: -13464.245 | C6: -6505.916 | D6: 83.178
A7: 112 | B7: -13502.559 | C7: -5307.985 | D7: 69.18
A8: 113 | B8: -13473.124 | C8: -4071.312 | D8: 61.003
A9: 114 | B9: -13502.548 | C9: -2908.279 | D9: 66.389
A10: 115 | B10: -13497.986 | C10: -1660.573 | D10: 72.207
A11: 116 | B11: -13494.465 | C11: -507.028 | D11: 84.541
A12: 205 | B12: -12295.799 | C12: -13715.371 | D12: 39.888
... A836: 7809 | B836: 9488.88 | C836: 48749.722 | D836: -51.691

Sheet TA_AllSites_20220124
A1: Latitude | B1: Longitude | C1: Name | K1: SN6903 | L1: =INDEX(A:A,match($K1,$C:$C,0)) -> 39.567144 | M1: =INDEX(B:B,match($K1,$C:$C,0)) -> -112.93245 | N1: BLM
A2: 39.29693 | B2: -112.90875 | C2: CLF | K2: SN6910 | L2: =INDEX(A:A,match($K2,$C:$C,0)) -> 39.567654 | M2: =INDEX(B:B,match($K2,$C:$C,0)) -> -112.76941 | N2: BLM
A3: 39.338505 | B3: -112.70089 | C3: fast_a | K3: KM7304 | L3: =INDEX(A:A,match($K3,$C:$C,0)) -> 39.64017 | M3: =INDEX(B:B,match($K3,$C:$C,0)) -> -112.91647 | N3: SITLA | O3: 250 | P3: ft
A4: 39.339457 | B4: -112.70183 | C4: INTF | K4: KM7310 | L4: =INDEX(A:A,match($K4,$C:$C,0)) -> 39.642594 | M4: =INDEX(B:B,match($K4,$C:$C,0)) -> -112.77133 | N4: SITLA | O4: 1000 | P4: ft
A5: 39.29228 | B5: -112.77308 | C5: slow_a | K5: SC4207 | L5: =INDEX(A:A,match($K5,$C:$C,0)) -> 39.023284 | M5: =INDEX(B:B,match($K5,$C:$C,0)) -> -112.82786 | N5: SITLA | O5: 380 | P5: ft
A6: 39.338417 | B6: -112.70109 | C6: slow_b | K6: SR4217 | L6: =INDEX(A:A,match($K6,$C:$C,0)) -> 39.026824 | M6: =INDEX(B:B,match($K6,$C:$C,0)) -> -112.5876 | N6: SITLA | O6: 1200 | P6: ft
A7: 39.296706 | B7: -112.90922 | C7: slow_c | K7: BF4612 | L7: =INDEX(A:A,match($K7,$C:$C,0)) -> 39.100144 | M7: =INDEX(B:B,match($K7,$C:$C,0)) -> -112.70947 | N7: BLM
A8: 39.378658 | B8: -112.88445 | C8: ta_a | K8: BF4717 | L8: =INDEX(A:A,match($K8,$C:$C,0)) -> 39.120474 | M8: =INDEX(B:B,match($K8,$C:$C,0)) -> -112.58976 | N8: SITLA | O8: 490 | P8: ft
A9: 39.389031 | B9: -112.81462 | C9: ta_b
A10: 39.189919 | B10: -112.71459 | C10: ta_c
A11: 39.472508 | B11: -112.99208 | C11: ta_d
A12: 39.281887 | B12: -113.06484 | C12: ta_e
A13: 39.206715 | B13: -113.12122 | C13: ta_f
A14: 39.140408 | B14: -112.78727 | C14: ta_g
A15: 39.216393 | B15: -112.82909 | C15: ta_h
A16: 39.248509 | B16: -112.88414 | C16: ta_i
A17: 39.291924 | B17: -112.77268 | C17: ta_j
A18: 39.338392 | B18: -112.69954 | C18: ta_k
A19: 39.469548 | B19: -113.00429 | C19: TI9001x
A20: 39.469572 | B20: -113.0043 | C20: TI9001
... A1397: 39.47866 | B1397: -112.87572 | C1397: TSFD

Sheet Sheet3
A1: A | B1: 39.29693 | C1: -112.90875 | E1: 39.338417 | F1: -112.70109 | G1: =LOOKUP(1,1/FREQUENCY(0,MMULT((B$1:C$10-E1:F1)^2,{1;1})),A$1:A$10) -> #N/A | H1: =LOOKUP(1,1/FREQUENCY(0,SIN((RADIANS(B$1:B$10-E1))/2)^2+SIN((RADIANS(C$1:C$10-F1))/2)^2*COS(RADIANS(B$1:B$10))*COS(RADIANS(E1))),A$1:A$10) -> A
A2: B | B2: 39.338505 | C2: -112.70089 | E2: 39.296706 | F2: -112.90922 | G2: =LOOKUP(1,1/FREQUENCY(0,MMULT((B$1:C$10-E2:F2)^2,{1;1})),A$1:A$10) -> #N/A | H2: =LOOKUP(1,1/FREQUENCY(0,SIN((RADIANS(B$1:B$10-E2))/2)^2+SIN((RADIANS(C$1:C$10-F2))/2)^2*COS(RADIANS(B$1:B$10))*COS(RADIANS(E2))),A$1:A$10) -> A
A3: C | B3: 39.339457 | C3: -112.70183 | E3: 39.378658 | F3: -112.88445 | G3: =LOOKUP(1,1/FREQUENCY(0,MMULT((B$1:C$10-E3:F3)^2,{1;1})),A$1:A$10) -> #N/A | H3: =LOOKUP(1,1/FREQUENCY(0,SIN((RADIANS(B$1:B$10-E3))/2)^2+SIN((RADIANS(C$1:C$10-F3))/2)^2*COS(RADIANS(B$1:B$10))*COS(RADIANS(E3))),A$1:A$10) -> A
A4: D | B4: 39.29228 | C4: -112.77308 | E4: 39.389031 | F4: -112.81462 | G4: =LOOKUP(1,1/FREQUENCY(0,MMULT((B$1:C$10-E4:F4)^2,{1;1})),A$1:A$10) -> #N/A | H4: =LOOKUP(1,1/FREQUENCY(0,SIN((RADIANS(B$1:B$10-E4))/2)^2+SIN((RADIANS(C$1:C$10-F4))/2)^2*COS(RADIANS(B$1:B$10))*COS(RADIANS(E4))),A$1:A$10) -> A
A5: E | B5: 39.338417 | C5: -112.70109 | E5: 39.189919 | F5: -112.71459 | G5: =LOOKUP(1,1/FREQUENCY(0,MMULT((B$1:C$10-E5:F5)^2,{1;1})),A$1:A$10) -> #N/A | H5: =LOOKUP(1,1/FREQUENCY(0,SIN((RADIANS(B$1:B$10-E5))/2)^2+SIN((RADIANS(C$1:C$10-F5))/2)^2*COS(RADIANS(B$1:B$10))*COS(RADIANS(E5))),A$1:A$10) -> A
A6: F | B6: 39.296706 | C6: -112.90922
A7: G | B7: 39.378658 | C7: -112.88445
A8: H | B8: 39.389031 | C8: -112.81462
A9: I | B9: 39.189919 | C9: -112.71459
A10: J | B10: 39.281887 | C10: -113.06484
